<?xml version="1.0" ?>
<!-- =================================================================================== -->
<!-- |    This document was autogenerated by xacro from mh5lsii_01.xacro               | -->
<!-- |    EDITING THIS FILE BY HAND IS NOT RECOMMENDED                                 | -->
<!-- =================================================================================== -->
<robot name="mh5lsii_01">
  <material name="silver">
    <color rgba="0.700 0.700 0.700 1.000"/>
  </material>
  <transmission name="Revolute 1_tran">
    <type>transmission_interface/SimpleTransmission</type>
    <joint name="Revolute 1">
      <hardwareInterface>hardware_interface/EffortJointInterface</hardwareInterface>
    </joint>
    <actuator name="Revolute 1_actr">
      <hardwareInterface>hardware_interface/EffortJointInterface</hardwareInterface>
      <mechanicalReduction>1</mechanicalReduction>
    </actuator>
  </transmission>
  <transmission name="Revolute 2_tran">
    <type>transmission_interface/SimpleTransmission</type>
    <joint name="Revolute 2">
      <hardwareInterface>hardware_interface/EffortJointInterface</hardwareInterface>
    </joint>
    <actuator name="Revolute 2_actr">
      <hardwareInterface>hardware_interface/EffortJointInterface</hardwareInterface>
      <mechanicalReduction>1</mechanicalReduction>
    </actuator>
  </transmission>
  <transmission name="Revolute 3_tran">
    <type>transmission_interface/SimpleTransmission</type>
    <joint name="Revolute 3">
      <hardwareInterface>hardware_interface/EffortJointInterface</hardwareInterface>
    </joint>
    <actuator name="Revolute 3_actr">
      <hardwareInterface>hardware_interface/EffortJointInterface</hardwareInterface>
      <mechanicalReduction>1</mechanicalReduction>
    </actuator>
  </transmission>
  <transmission name="Slider 4_tran">
    <type>transmission_interface/SimpleTransmission</type>
    <joint name="Slider 4">
      <hardwareInterface>hardware_interface/EffortJointInterface</hardwareInterface>
    </joint>
    <actuator name="Slider 4_actr">
      <hardwareInterface>hardware_interface/EffortJointInterface</hardwareInterface>
      <mechanicalReduction>1</mechanicalReduction>
    </actuator>
  </transmission>
  <transmission name="Revolute 5_tran">
    <type>transmission_interface/SimpleTransmission</type>
    <joint name="Revolute 5">
      <hardwareInterface>hardware_interface/EffortJointInterface</hardwareInterface>
    </joint>
    <actuator name="Revolute 5_actr">
      <hardwareInterface>hardware_interface/EffortJointInterface</hardwareInterface>
      <mechanicalReduction>1</mechanicalReduction>
    </actuator>
  </transmission>
  <transmission name="Revolute 6_tran">
    <type>transmission_interface/SimpleTransmission</type>
    <joint name="Revolute 6">
      <hardwareInterface>hardware_interface/EffortJointInterface</hardwareInterface>
    </joint>
    <actuator name="Revolute 6_actr">
      <hardwareInterface>hardware_interface/EffortJointInterface</hardwareInterface>
      <mechanicalReduction>1</mechanicalReduction>
    </actuator>
  </transmission>
  <transmission name="Revolute 7_tran">
    <type>transmission_interface/SimpleTransmission</type>
    <joint name="Revolute 7">
      <hardwareInterface>hardware_interface/EffortJointInterface</hardwareInterface>
    </joint>
    <actuator name="Revolute 7_actr">
      <hardwareInterface>hardware_interface/EffortJointInterface</hardwareInterface>
      <mechanicalReduction>1</mechanicalReduction>
    </actuator>
  </transmission>
  
  <link name="base_link">
    <inertial>
      <mass value="4.362"/>
      <inertia ixx="0.012" ixy="0.0" ixz="0.0" iyy="0.011" iyz="0.0" izz="0.023"/>
    </inertial>
    <visual>
      <origin rpy="0 0 0" xyz="0 0 0"/>
      <geometry>
        <mesh filename="package://mh5lsii_01_description/meshes/base_link.stl" scale="0.001 0.001 0.001"/>
      </geometry>
      <material name="silver"/>
    </visual>
    <collision>
      <origin rpy="0 0 0" xyz="0 0 0"/>
      <geometry>
        <mesh filename="package://mh5lsii_01_description/meshes/base_link.stl" scale="0.001 0.001 0.001"/>
      </geometry>
    </collision>
  </link>
  <link name="mh5lsii_03_v1_1">
    <inertial>
      <mass value="10.871"/>
      <inertia ixx="0.0587" ixy="0.0" ixz="0.0" iyy="0.0587" iyz="0.0" izz="0.0587"/>
    </inertial>
    <visual>
      <origin rpy="0 0 0" xyz="-0.0 -0.0 -0.229"/>
      <geometry>
        <mesh filename="package://mh5lsii_01_description/meshes/mh5lsii_03_v1_1.stl" scale="0.001 0.001 0.001"/>
      </geometry>
      <material name="silver"/>
    </visual>
    <collision>
      <origin rpy="0 0 0" xyz="-0.0 -0.0 -0.229"/>
      <geometry>
        <mesh filename="package://mh5lsii_01_description/meshes/mh5lsii_03_v1_1.stl" scale="0.001 0.001 0.001"/>
      </geometry>
    </collision>
  </link>
  <link name="mh5lsii_04_v1_1">
    <inertial>
      <mass value="4.594"/>
      <inertia ixx="0.16" ixy="0.0" ixz="0.003" iyy="0.2" iyz="0.0" izz="0.0"/>
    </inertial>
    <visual>
      <origin rpy="0 0 0" xyz="0.0555 -0.088 -0.33"/>
      <geometry>
        <mesh filename="package://mh5lsii_01_description/meshes/mh5lsii_04_v1_1.stl" scale="0.001 0.001 0.001"/>
      </geometry>
      <material name="silver"/>
    </visual>
    <collision>
      <origin rpy="0 0 0" xyz="0.0555 -0.088 -0.33"/>
      <geometry>
        <mesh filename="package://mh5lsii_01_description/meshes/mh5lsii_04_v1_1.stl" scale="0.001 0.001 0.001"/>
      </geometry>
    </collision>
  </link>
  <link name="mh5lsii_05_v1_1">
    <inertial>
      <mass value="9.979"/>
      <inertia ixx="0.168" ixy="0.001" ixz="0.002" iyy="0.117" iyz="0.002" izz="0.117"/>
    </inertial>
    <visual>
      <origin rpy="0 0 0" xyz="0.0625 -0.088 -0.73"/>
      <geometry>
        <mesh filename="package://mh5lsii_01_description/meshes/mh5lsii_05_v1_1.stl" scale="0.001 0.001 0.001"/>
      </geometry>
      <material name="silver"/>
    </visual>
    <collision>
      <origin rpy="0 0 0" xyz="0.0625 -0.088 -0.73"/>
      <geometry>
        <mesh filename="package://mh5lsii_01_description/meshes/mh5lsii_05_v1_1.stl" scale="0.001 0.001 0.001"/>
      </geometry>
    </collision>
  </link>
  <link name="m5h_intermedio56_v2_1">
    <inertial>
      <mass value="4.862"/>
      <inertia ixx="0.14" ixy="0.0" ixz="0.001" iyy="0.17" iyz="0.0" izz="0.15"/>
    </inertial>
    <visual>
      <origin rpy="0 0 0" xyz="-0.0005 -0.1585 -0.77"/>
      <geometry>
        <mesh filename="package://mh5lsii_01_description/meshes/m5h_intermedio56_v2_1.stl" scale="0.001 0.001 0.001"/>
      </geometry>
      <material name="silver"/>
    </visual>
    <collision>
      <origin rpy="0 0 0" xyz="-0.0005 -0.1585 -0.77"/>
      <geometry>
        <mesh filename="package://mh5lsii_01_description/meshes/m5h_intermedio56_v2_1.stl" scale="0.001 0.001 0.001"/>
      </geometry>
    </collision>
  </link>
  <link name="mh5lsii_06_v1_1">
    <inertial>
      <mass value="3.891"/>
      <inertia ixx="0.06" ixy="0.0" ixz="0.0" iyy="0.23" iyz="0.0" izz="0.24"/>
    </inertial>
    <visual>
      <origin rpy="0 0 0" xyz="-0.0005 -0.2885 -0.77"/>
      <geometry>
        <mesh filename="package://mh5lsii_01_description/meshes/mh5lsii_06_v1_1.stl" scale="0.001 0.001 0.001"/>
      </geometry>
      <material name="silver"/>
    </visual>
    <collision>
      <origin rpy="0 0 0" xyz="-0.0005 -0.2885 -0.77"/>
      <geometry>
        <mesh filename="package://mh5lsii_01_description/meshes/mh5lsii_06_v1_1.stl" scale="0.001 0.001 0.001"/>
      </geometry>
    </collision>
  </link>
  <link name="mh5lsii_07_v1_1">
    <inertial>
      <mass value="0.747"/>
      <inertia ixx="0.2" ixy="0.0" ixz="0.0" iyy="0.2" iyz="0.0" izz="0.2"/>
    </inertial>
    <visual>
      <origin rpy="0 0 0" xyz="-0.0315 -0.622 -0.77"/>
      <geometry>
        <mesh filename="package://mh5lsii_01_description/meshes/mh5lsii_07_v1_1.stl" scale="0.001 0.001 0.001"/>
      </geometry>
      <material name="silver"/>
    </visual>
    <collision>
      <origin rpy="0 0 0" xyz="-0.0315 -0.622 -0.77"/>
      <geometry>
        <mesh filename="package://mh5lsii_01_description/meshes/mh5lsii_07_v1_1.stl" scale="0.001 0.001 0.001"/>
      </geometry>
    </collision>
  </link>
  <link name="mh5lsii_08_v1_1">
    <inertial>
      <mass value="0.03"/>
      <inertia ixx="0.01" ixy="0.0" ixz="0.0" iyy="0.066" iyz="0.0" izz="0.0065"/>
    </inertial>
    <visual>
      <origin rpy="0 0 0" xyz="-0.0015 -0.6725 -0.77"/>
      <geometry>
        <mesh filename="package://mh5lsii_01_description/meshes/mh5lsii_08_v1_1.stl" scale="0.001 0.001 0.001"/>
      </geometry>
      <material name="silver"/>
    </visual>
    <collision>
      <origin rpy="0 0 0" xyz="-0.0015 -0.6725 -0.77"/>
      <geometry>
        <mesh filename="package://mh5lsii_01_description/meshes/mh5lsii_08_v1_1.stl" scale="0.001 0.001 0.001"/>
      </geometry>
    </collision>
  </link>
  <joint name="Revolute 1" type="revolute">
    <origin rpy="0 0 0" xyz="0.0 0.0 0.229"/>
    <parent link="base_link"/>
    <child link="mh5lsii_03_v1_1"/>
    <axis xyz="0.0 0.0 1.0"/>
    <limit effort="100" lower="-2.96706" upper="2.96706" velocity="100"/>
    <dynamics damping = "50" friction = "1"/>
  </joint>
  <joint name="Revolute 2" type="revolute">
    <origin rpy="0 0 0" xyz="-0.0555 0.088 0.101"/>
    <parent link="mh5lsii_03_v1_1"/>
    <child link="mh5lsii_04_v1_1"/>
    <axis xyz="-1.0 0.0 0.0"/>
    <limit effort="100" lower="-1.134464" upper="2.617994" velocity="100"/>
    <dynamics damping = "50" friction = "1"/>
  </joint>
  <joint name="Revolute 3" type="revolute">
    <origin rpy="0 0 0" xyz="-0.007 0.0 0.4"/>
    <parent link="mh5lsii_04_v1_1"/>
    <child link="mh5lsii_05_v1_1"/>
    <axis xyz="1.0 0.0 0.0"/>
    <limit effort="100" lower="-1.134464" upper="2.70526" velocity="100"/>
    <dynamics damping = "50" friction = "1"/>
  </joint>
  <joint name="Slider 4" type="prismatic">
    <origin rpy="0 0 0" xyz="0.063 0.0705 0.04"/>
    <parent link="mh5lsii_05_v1_1"/>
    <child link="m5h_intermedio56_v2_1"/>
    <axis xyz="0.0 1.0 0.0"/>
    <limit effort="100" lower="0.0" upper="0.05" velocity="100"/>
    <dynamics damping = "50" friction = "1"/>
  </joint>
  <joint name="Revolute 5" type="revolute">
    <origin rpy="0 0 0" xyz="0.0 0.13 0.0"/>
    <parent link="m5h_intermedio56_v2_1"/>
    <child link="mh5lsii_06_v1_1"/>
    <axis xyz="0.0 1.0 0.0"/>
    <limit effort="100" lower="-2.96706" upper="3.316126" velocity="100"/>
    <dynamics damping = "50" friction = "1"/>
  </joint>
  <joint name="Revolute 6" type="revolute">
    <origin rpy="0 0 0" xyz="0.031 0.3335 0.0"/>
    <parent link="mh5lsii_06_v1_1"/>
    <child link="mh5lsii_07_v1_1"/>
    <axis xyz="-1.0 0.0 0.0"/>
    <limit effort="100" lower="-2.356194" upper="2.356194" velocity="100"/>
    <dynamics damping = "50" friction = "1"/>
  </joint>
  <joint name="Revolute 7" type="continuous">
    <origin rpy="0 0 0" xyz="-0.03 0.0505 0.0"/>
    <parent link="mh5lsii_07_v1_1"/>
    <child link="mh5lsii_08_v1_1"/>
    <axis xyz="0.0 1.0 0.0"/>
    <dynamics damping = "50" friction = "1"/>
  </joint>
</robot>
