<?xml version="1.0" ?>
<robot name="mh5lsii_01" xmlns:xacro="http://www.ros.org/wiki/xacro">

<xacro:include filename="$(find mh5lsii_01_description)/urdf/materials.xacro" />
<xacro:include filename="$(find mh5lsii_01_description)/urdf/mh5lsii_01.trans" />
<xacro:include filename="$(find mh5lsii_01_description)/urdf/mh5lsii_01.gazebo" />
<link name="base_link">
  <visual>
    <origin xyz="0 0 0" rpy="0 0 0"/>
    <geometry>
      <mesh filename="package://mh5lsii_01_description/meshes/base_link.stl" scale="0.001 0.001 0.001"/>
    </geometry>
    <material name="silver"/>
  </visual>
  <collision>
    <origin xyz="0 0 0" rpy="0 0 0"/>
    <geometry>
      <mesh filename="package://mh5lsii_01_description/meshes/base_link.stl" scale="0.001 0.001 0.001"/>
    </geometry>
  </collision>
</link>

<link name="mh5lsii_03_v1_1">
  <visual>
    <origin xyz="-0.0 -0.0 -0.229" rpy="0 0 0"/>
    <geometry>
      <mesh filename="package://mh5lsii_01_description/meshes/mh5lsii_03_v1_1.stl" scale="0.001 0.001 0.001"/>
    </geometry>
    <material name="silver"/>
  </visual>
  <collision>
    <origin xyz="-0.0 -0.0 -0.229" rpy="0 0 0"/>
    <geometry>
      <mesh filename="package://mh5lsii_01_description/meshes/mh5lsii_03_v1_1.stl" scale="0.001 0.001 0.001"/>
    </geometry>
  </collision>
</link>

<link name="mh5lsii_04_v1_1">
  <visual>
    <origin xyz="0.0555 -0.088 -0.33" rpy="0 0 0"/>
    <geometry>
      <mesh filename="package://mh5lsii_01_description/meshes/mh5lsii_04_v1_1.stl" scale="0.001 0.001 0.001"/>
    </geometry>
    <material name="silver"/>
  </visual>
  <collision>
    <origin xyz="0.0555 -0.088 -0.33" rpy="0 0 0"/>
    <geometry>
      <mesh filename="package://mh5lsii_01_description/meshes/mh5lsii_04_v1_1.stl" scale="0.001 0.001 0.001"/>
    </geometry>
  </collision>
</link>

<link name="mh5lsii_05_v1_1">
  <visual>
    <origin xyz="0.0625 -0.088 -0.73" rpy="0 0 0"/>
    <geometry>
      <mesh filename="package://mh5lsii_01_description/meshes/mh5lsii_05_v1_1.stl" scale="0.001 0.001 0.001"/>
    </geometry>
    <material name="silver"/>
  </visual>
  <collision>
    <origin xyz="0.0625 -0.088 -0.73" rpy="0 0 0"/>
    <geometry>
      <mesh filename="package://mh5lsii_01_description/meshes/mh5lsii_05_v1_1.stl" scale="0.001 0.001 0.001"/>
    </geometry>
  </collision>
</link>

<link name="m5h_intermedio56_v2_1">
  <visual>
    <origin xyz="-0.0005 -0.1585 -0.77" rpy="0 0 0"/>
    <geometry>
      <mesh filename="package://mh5lsii_01_description/meshes/m5h_intermedio56_v2_1.stl" scale="0.001 0.001 0.001"/>
    </geometry>
    <material name="silver"/>
  </visual>
  <collision>
    <origin xyz="-0.0005 -0.1585 -0.77" rpy="0 0 0"/>
    <geometry>
      <mesh filename="package://mh5lsii_01_description/meshes/m5h_intermedio56_v2_1.stl" scale="0.001 0.001 0.001"/>
    </geometry>
  </collision>
</link>

<link name="mh5lsii_06_v1_1">
  <visual>
    <origin xyz="-0.0005 -0.2885 -0.77" rpy="0 0 0"/>
    <geometry>
      <mesh filename="package://mh5lsii_01_description/meshes/mh5lsii_06_v1_1.stl" scale="0.001 0.001 0.001"/>
    </geometry>
    <material name="silver"/>
  </visual>
  <collision>
    <origin xyz="-0.0005 -0.2885 -0.77" rpy="0 0 0"/>
    <geometry>
      <mesh filename="package://mh5lsii_01_description/meshes/mh5lsii_06_v1_1.stl" scale="0.001 0.001 0.001"/>
    </geometry>
  </collision>
</link>

<link name="mh5lsii_07_v1_1">
  <visual>
    <origin xyz="-0.0315 -0.622 -0.77" rpy="0 0 0"/>
    <geometry>
      <mesh filename="package://mh5lsii_01_description/meshes/mh5lsii_07_v1_1.stl" scale="0.001 0.001 0.001"/>
    </geometry>
    <material name="silver"/>
  </visual>
  <collision>
    <origin xyz="-0.0315 -0.622 -0.77" rpy="0 0 0"/>
    <geometry>
      <mesh filename="package://mh5lsii_01_description/meshes/mh5lsii_07_v1_1.stl" scale="0.001 0.001 0.001"/>
    </geometry>
  </collision>
</link>

<link name="mh5lsii_08_v1_1">
  <visual>
    <origin xyz="-0.0015 -0.6725 -0.77" rpy="0 0 0"/>
    <geometry>
      <mesh filename="package://mh5lsii_01_description/meshes/mh5lsii_08_v1_1.stl" scale="0.001 0.001 0.001"/>
    </geometry>
    <material name="silver"/>
  </visual>
  <collision>
    <origin xyz="-0.0015 -0.6725 -0.77" rpy="0 0 0"/>
    <geometry>
      <mesh filename="package://mh5lsii_01_description/meshes/mh5lsii_08_v1_1.stl" scale="0.001 0.001 0.001"/>
    </geometry>
  </collision>
</link>

<joint name="Revolute 1" type="revolute">
  <origin xyz="0.0 0.0 0.229" rpy="0 0 0"/>
  <parent link="base_link"/>
  <child link="mh5lsii_03_v1_1"/>
  <axis xyz="0.0 0.0 1.0"/>
  <limit upper="2.96706" lower="-2.96706" effort="100" velocity="100"/>
</joint>

<joint name="Revolute 2" type="revolute">
  <origin xyz="-0.0555 0.088 0.101" rpy="0 0 0"/>
  <parent link="mh5lsii_03_v1_1"/>
  <child link="mh5lsii_04_v1_1"/>
  <axis xyz="-1.0 0.0 0.0"/>
  <limit upper="2.617994" lower="-1.134464" effort="100" velocity="100"/>
</joint>

<joint name="Revolute 3" type="revolute">
  <origin xyz="-0.007 0.0 0.4" rpy="0 0 0"/>
  <parent link="mh5lsii_04_v1_1"/>
  <child link="mh5lsii_05_v1_1"/>
  <axis xyz="1.0 0.0 0.0"/>
  <limit upper="2.70526" lower="-1.134464" effort="100" velocity="100"/>
</joint>

<joint name="Slider 4" type="prismatic">
  <origin xyz="0.063 0.0705 0.04" rpy="0 0 0"/>
  <parent link="mh5lsii_05_v1_1"/>
  <child link="m5h_intermedio56_v2_1"/>
  <axis xyz="0.0 1.0 0.0"/>
  <limit upper="0.05" lower="0.0" effort="100" velocity="100"/>
</joint>

<joint name="Revolute 5" type="revolute">
  <origin xyz="0.0 0.13 0.0" rpy="0 0 0"/>
  <parent link="m5h_intermedio56_v2_1"/>
  <child link="mh5lsii_06_v1_1"/>
  <axis xyz="0.0 1.0 0.0"/>
  <limit upper="3.316126" lower="-2.96706" effort="100" velocity="100"/>
</joint>

<joint name="Revolute 6" type="revolute">
  <origin xyz="0.031 0.3335 0.0" rpy="0 0 0"/>
  <parent link="mh5lsii_06_v1_1"/>
  <child link="mh5lsii_07_v1_1"/>
  <axis xyz="-1.0 0.0 0.0"/>
  <limit upper="2.356194" lower="-2.356194" effort="100" velocity="100"/>
</joint>

<joint name="Revolute 7" type="continuous">
  <origin xyz="-0.03 0.0505 0.0" rpy="0 0 0"/>
  <parent link="mh5lsii_07_v1_1"/>
  <child link="mh5lsii_08_v1_1"/>
  <axis xyz="0.0 1.0 0.0"/>
</joint>

</robot>
